ERROR - 2021-03-18 14:24:29 --> Error connecting to the database: Nenhuma conexão pôde ser feita porque a máquina de destino as recusou ativamente.

CRITICAL - 2021-03-18 14:24:29 --> Unable to connect to the database.
#0 C:\xampp\htdocs\encurtador\vendor\codeigniter4\framework\system\Database\BaseConnection.php(618): CodeIgniter\Database\BaseConnection->initialize()
#1 C:\xampp\htdocs\encurtador\vendor\codeigniter4\framework\system\Database\BaseBuilder.php(1866): CodeIgniter\Database\BaseConnection->query('SELECT *\nFROM `...', Array, false)
#2 C:\xampp\htdocs\encurtador\vendor\codeigniter4\framework\system\Model.php(247): CodeIgniter\Database\BaseBuilder->get()
#3 C:\xampp\htdocs\encurtador\vendor\codeigniter4\framework\system\BaseModel.php(624): CodeIgniter\Model->doFirst()
#4 C:\xampp\htdocs\encurtador\app\Models\UsuarioModel.php(58): CodeIgniter\BaseModel->first()
#5 C:\xampp\htdocs\encurtador\app\Controllers\Login.php(38): App\Models\UsuarioModel->getByEmail('reszko@gmail.co...')
#6 C:\xampp\htdocs\encurtador\vendor\codeigniter4\framework\system\CodeIgniter.php(936): App\Controllers\Login->signin()
#7 C:\xampp\htdocs\encurtador\vendor\codeigniter4\framework\system\CodeIgniter.php(432): CodeIgniter\CodeIgniter->runController(Object(App\Controllers\Login))
#8 C:\xampp\htdocs\encurtador\vendor\codeigniter4\framework\system\CodeIgniter.php(333): CodeIgniter\CodeIgniter->handleRequest(NULL, Object(Config\Cache), false)
#9 C:\xampp\htdocs\encurtador\public\index.php(42): CodeIgniter\CodeIgniter->run()
#10 C:\xampp\htdocs\encurtador\vendor\codeigniter4\framework\system\Commands\Server\rewrite.php(45): require_once('C:\\xampp\\htdocs...')
#11 {main}
CRITICAL - 2021-03-18 14:24:29 --> Uncaught ErrorException: print_r(): Property access is not allowed yet in C:\xampp\htdocs\encurtador\app\Views\errors\html\error_exception.php:100
Stack trace:
#0 [internal function]: CodeIgniter\Debug\Exceptions->errorHandler(2, 'print_r(): Prop...', 'C:\\xampp\\htdocs...', 100, Array)
#1 C:\xampp\htdocs\encurtador\app\Views\errors\html\error_exception.php(100): print_r(Object(App\Controllers\Login), true)
#2 C:\xampp\htdocs\encurtador\vendor\codeigniter4\framework\system\Debug\Exceptions.php(281): include('C:\\xampp\\htdocs...')
#3 C:\xampp\htdocs\encurtador\vendor\codeigniter4\framework\system\Debug\Exceptions.php(147): CodeIgniter\Debug\Exceptions->render(Object(CodeIgniter\Database\Exceptions\DatabaseException), 500)
#4 [internal function]: CodeIgniter\Debug\Exceptions->exceptionHandler(Object(CodeIgniter\Database\Exceptions\DatabaseException))
#5 {main}
  thrown
#0 [internal function]: CodeIgniter\Debug\Exceptions->shutdownHandler()
#1 {main}
